<?xml version="1.0"?>
<robot name="box_bot" xmlns:xacro="http://www.ros.org/wiki/xacro">

  <link name="base_link"/>

  <joint name="chassis_joint" type="fixed">
    <parent link="base_link"/>
    <child link="chassis"/>
    <origin xyz="0 0 0.1"/>
  </joint>

  <link name="chassis">
    <visual>
      <geometry><box size="0.4 0.3 0.15"/></geometry>
      <material name="blue"><color rgba="0 0 0.8 1"/></material>
    </visual>
    <collision>
      <geometry><box size="0.4 0.3 0.15"/></geometry>
    </collision>
    <inertial>
      <mass value="1.0"/>
      <inertia ixx="0.01" ixy="0" ixz="0" iyy="0.01" iyz="0" izz="0.01"/>
    </inertial>
  </link>

  <link name="left_wheel">
    <visual>
      <geometry><cylinder radius="0.1" length="0.04"/></geometry>
      <material name="black"><color rgba="0 0 0 1"/></material>
    </visual>
    <collision>
      <geometry><cylinder radius="0.1" length="0.04"/></geometry>
    </collision>
    <inertial>
      <mass value="0.1"/>
      <inertia ixx="0.001" ixy="0" ixz="0" iyy="0.001" iyz="0" izz="0.001"/>
    </inertial>
  </link>

  <joint name="left_wheel_joint" type="continuous">
    <parent link="chassis"/>
    <child link="left_wheel"/>
    <origin xyz="0 0.175 -0.05" rpy="-1.5708 0 0"/>
    <axis xyz="0 0 1"/>
  </joint>

  <link name="right_wheel">
    <visual>
      <geometry><cylinder radius="0.1" length="0.04"/></geometry>
      <material name="black"><color rgba="0 0 0 1"/></material>
    </visual>
    <collision>
      <geometry><cylinder radius="0.1" length="0.04"/></geometry>
    </collision>
    <inertial>
      <mass value="0.1"/>
      <inertia ixx="0.001" ixy="0" ixz="0" iyy="0.001" iyz="0" izz="0.001"/>
    </inertial>
  </link>

  <joint name="right_wheel_joint" type="continuous">
    <parent link="chassis"/>
    <child link="right_wheel"/>
    <origin xyz="0 -0.175 -0.05" rpy="1.5708 0 0"/>
    <axis xyz="0 0 1"/>
  </joint>

  <link name="caster">
    <visual>
      <geometry><sphere radius="0.05"/></geometry>
    </visual>
    <collision>
      <geometry><sphere radius="0.05"/></geometry>
    </collision>
    <inertial>
      <mass value="0.1"/>
      <inertia ixx="0.0001" ixy="0" ixz="0" iyy="0.0001" iyz="0" izz="0.0001"/>
    </inertial>
  </link>

  <joint name="caster_joint" type="fixed">
    <parent link="chassis"/>
    <child link="caster"/>
    <origin xyz="0.15 0 -0.1"/>
  </joint>

  <gazebo>
    <plugin filename="gz-sim-diff-drive-system" name="gz::sim::systems::DiffDrive">
      <left_joint>left_wheel_joint</left_joint>
      <right_joint>right_wheel_joint</right_joint>
      <wheel_separation>0.35</wheel_separation>
      <wheel_radius>0.1</wheel_radius>
      <topic>cmd_vel</topic>
      <odom_topic>odom</odom_topic>
      <frame_id>odom</frame_id>
      <child_frame_id>base_link</child_frame_id>
    </plugin>
    <plugin filename="gz-sim-joint-state-publisher-system" name="gz::sim::systems::JointStatePublisher"/>
  </gazebo>

</robot>
